<?xml version="1.0"?>
<robot name="lite6">

  <!-- Link: base -->
  <link name="link_base">
    <inertial>
      <origin xyz="-0.00829544579053192 3.26357432323433E-05 0.0631194584987089" rpy="0 0 0"/>
      <mass value="1.65393501783165"/>
      <!-- Note: the inertia matrix values in your xacro are zero (ixx, iyy, izz = 0) —
           you should replace them by real nonzero inertia values. -->
      <inertia
        ixx="0" ixy="0" ixz="0"
        iyy="0" iyz="0" izz="0"/>
    </inertial>
    <!-- Visual & collision meshes (fill in correct mesh files / origins) -->
    <visual>
      <origin xyz="0 0 0" rpy="0 0 0"/>
      <geometry>
        <mesh filename="visual/link_base.stl"/>
      </geometry>
      <material name="White">
        <color rgba="1 1 1 1"/>
      </material>
    </visual>
    <collision>
      <origin xyz="0 0 0" rpy="0 0 0"/>
      <geometry>
        <mesh filename="collision/link_base.stl"/>
      </geometry>
    </collision>
  </link>

  <!-- Link1 -->
  <link name="link1">
    <inertial>
      <!-- You need to fill origin, mass, inertia from your inertial_params['link1'] -->
      <origin xyz="0 0 0" rpy="0 0 0"/>
      <mass value="1.0"/>
      <inertia ixx="0.01" ixy="0" ixz="0" iyy="0.01" iyz="0" izz="0.01"/>
    </inertial>
    <visual>
      <origin xyz="0 0 0" rpy="0 0 0"/>
      <geometry>
        <mesh filename="visual/link1.stl"/>
      </geometry>
      <material name="White">
        <color rgba="1 1 1 1"/>
      </material>
    </visual>
    <collision>
      <origin xyz="0 0 0" rpy="0 0 0"/>
      <geometry>
        <mesh filename="collision/link1.stl"/>
      </geometry>
    </collision>
  </link>

  <joint name="joint1" type="revolute">
    <origin xyz="0 0 0" rpy="0 0 0"/>  <!-- adjust from kinematics_params['joint1'] -->
    <parent link="link_base"/>
    <child link="link1"/>
    <axis xyz="0 0 1"/>
    <limit lower="-6.283185307179586" upper="6.283185307179586" effort="50.0" velocity="3.14"/>
    <dynamics damping="1.0" friction="1.0"/>
  </joint>

  <!-- Link2 -->
  <link name="link2">
    <inertial>
      <!-- fill from inertial_params['link2'] -->
      <origin xyz="0 0 0" rpy="0 0 0"/>
      <mass value="1.0"/>
      <inertia ixx="0.01" ixy="0" ixz="0" iyy="0.01" iyz="0" izz="0.01"/>
    </inertial>
    <visual>
      <origin xyz="0 0 0" rpy="0 0 0"/>
      <geometry>
        <mesh filename="visual/link2.stl"/>
      </geometry>
      <material name="White">
        <color rgba="1 1 1 1"/>
      </material>
    </visual>
    <collision>
      <origin xyz="0 0 0" rpy="0 0 0"/>
      <geometry>
        <mesh filename="collision/link2.stl"/>
      </geometry>
    </collision>
  </link>

  <joint name="joint2" type="revolute">
    <origin xyz="0 0 0" rpy="0 0 0"/>  <!-- adjust from kinematics_params['joint2'] -->
    <parent link="link1"/>
    <child link="link2"/>
    <axis xyz="0 0 1"/>
    <limit lower="-2.61799" upper="2.61799" effort="50.0" velocity="3.14"/>
    <dynamics damping="1.0" friction="1.0"/>
  </joint>

  <!-- Link3 -->
  <link name="link3">
    <inertial>
      <!-- fill from inertial_params['link3'] -->
      <origin xyz="0 0 0" rpy="0 0 0"/>
      <mass value="1.0"/>
      <inertia ixx="0.01" ixy="0" ixz="0" iyy="0.01" iyz="0" izz="0.01"/>
    </inertial>
    <visual>
      <origin xyz="0 0 0" rpy="0 0 0"/>
      <geometry>
        <mesh filename="visual/link3.stl"/>
      </geometry>
      <material name="White">
        <color rgba="1 1 1 1"/>
      </material>
    </visual>
    <collision>
      <origin xyz="0 0 0" rpy="0 0 0"/>
      <geometry>
        <mesh filename="collision/link3.stl"/>
      </geometry>
    </collision>
  </link>

  <joint name="joint3" type="revolute">
    <origin xyz="0 0 0" rpy="0 0 0"/>  <!-- adjust from kinematics_params['joint3'] -->
    <parent link="link2"/>
    <child link="link3"/>
    <axis xyz="0 0 1"/>
    <limit lower="-0.061087" upper="5.235988" effort="32.0" velocity="3.14"/>
    <dynamics damping="1.0" friction="1.0"/>
  </joint>

  <!-- Link4 -->
  <link name="link4">
    <inertial>
      <!-- fill from inertial_params['link4'] -->
      <origin xyz="0 0 0" rpy="0 0 0"/>
      <mass value="1.0"/>
      <inertia ixx="0.01" ixy="0" ixz="0" iyy="0.01" iyz="0" izz="0.01"/>
    </inertial>
    <visual>
      <origin xyz="0 0 0" rpy="0 0 0"/>
      <geometry>
        <mesh filename="visual/link4.stl"/>
      </geometry>
      <material name="White">
        <color rgba="1 1 1 1"/>
      </material>
    </visual>
    <collision>
      <origin xyz="0 0 0" rpy="0 0 0"/>
      <geometry>
        <mesh filename="collision/link4.stl"/>
      </geometry>
    </collision>
  </link>

  <joint name="joint4" type="revolute">
    <origin xyz="0 0 0" rpy="0 0 0"/>  <!-- adjust from kinematics_params['joint4'] -->
    <parent link="link3"/>
    <child link="link4"/>
    <axis xyz="0 0 1"/>
    <limit lower="-6.283185307179586" upper="6.283185307179586" effort="32.0" velocity="3.14"/>
    <dynamics damping="1.0" friction="1.0"/>
  </joint>

  <!-- Link5 -->
  <link name="link5">
    <inertial>
      <!-- fill from inertial_params['link5'] -->
      <origin xyz="0 0 0" rpy="0 0 0"/>
      <mass value="1.0"/>
      <inertia ixx="0.01" ixy="0" ixz="0" iyy="0.01" iyz="0" izz="0.01"/>
    </inertial>
    <visual>
      <origin xyz="0 0 0" rpy="0 0 0"/>
      <geometry>
        <mesh filename="visual/link5.stl"/>
      </geometry>
      <material name="White">
        <color rgba="1 1 1 1"/>
      </material>
    </visual>
    <collision>
      <origin xyz="0 0 0" rpy="0 0 0"/>
      <geometry>
        <mesh filename="collision/link5.stl"/>
      </geometry>
    </collision>
  </link>

  <joint name="joint5" type="revolute">
    <origin xyz="0 0 0" rpy="0 0 0"/>  <!-- adjust from kinematics_params['joint5'] -->
    <parent link="link4"/>
    <child link="link5"/>
    <axis xyz="0 0 1"/>
    <limit lower="-2.1642" upper="2.1642" effort="32.0" velocity="3.14"/>
    <dynamics damping="1.0" friction="1.0"/>
  </joint>

  <!-- Link6 -->
  <link name="link6">
    <inertial>
      <!-- fill from inertial_params['link6'] -->
      <origin xyz="0 0 0" rpy="0 0 0"/>
      <mass value="1.0"/>
      <inertia ixx="0.01" ixy="0" ixz="0" iyy="0.01" iyz="0" izz="0.01"/>
    </inertial>
    <visual>
      <origin xyz="0 0 0" rpy="0 0 0"/>
      <geometry>
        <mesh filename="visual/link6.stl"/>
      </geometry>
      <material name="Silver">
        <color rgba="0.75 0.75 0.75 1"/>
      </material>
    </visual>
    <collision>
      <origin xyz="0 0 0" rpy="0 0 0"/>
      <geometry>
        <mesh filename="collision/link6.stl"/>
      </geometry>
    </collision>
  </link>

  <joint name="joint6" type="revolute">
    <origin xyz="0 0 0" rpy="0 0 0"/>  <!-- adjust from kinematics_params['joint6'] -->
    <parent link="link5"/>
    <child link="link6"/>
    <axis xyz="0 0 1"/>
    <limit lower="-6.283185307179586" upper="6.283185307179586" effort="20.0" velocity="3.14"/>
    <dynamics damping="1.0" friction="1.0"/>
  </joint>

</robot>
